Workbook
Name CO_BIN: #REF!
Name CO_Commissionerate: #REF!
Name CO_Declaration: #REF!
Name CO_Division: #REF!
Name CO_ExporterAddr: #REF!
Name CO_ExporterName: #REF!
Name CO_GSTIN: #REF!
Name CO_IEC: #REF!
Name CO_Origin: #REF!
Name CO_PlaceReceipt: #REF!
Name CO_PortLoading: #REF!
Name CO_Range: #REF!
Name CO_Tel: #REF!
Name L_AccessoriesItem: OFFSET('Master Lists'!$G$5,0,0,COUNTA('Master Lists'!$G$5:$G$500),1)
Name L_AuthorisedBy: OFFSET('Master Lists'!$AD$5,0,0,COUNTA('Master Lists'!$AD$5:$AD$500),1)
Name L_ColorCode: OFFSET('Master Lists'!$H$5,0,0,COUNTA('Master Lists'!$H$5:$H$500),1)
Name L_Construction: OFFSET('Master Lists'!$L$5,0,0,COUNTA('Master Lists'!$L$5:$L$500),1)
Name L_ContainerNo: OFFSET('Master Lists'!$Q$5,0,0,COUNTA('Master Lists'!$Q$5:$Q$500),1)
Name L_Count: OFFSET('Master Lists'!$K$5,0,0,COUNTA('Master Lists'!$K$5:$K$500),1)
Name L_Country: OFFSET('Master Lists'!$A$5,0,0,COUNTA('Master Lists'!$A$5:$A$500),1)
Name L_Currency: OFFSET('Master Lists'!$B$5,0,0,COUNTA('Master Lists'!$B$5:$B$500),1)
Name L_Decision: OFFSET('Master Lists'!$AF$5,0,0,COUNTA('Master Lists'!$AF$5:$AF$500),1)
Name L_DefectType: OFFSET('Master Lists'!$V$5,0,0,COUNTA('Master Lists'!$V$5:$V$500),1)
Name L_Department: OFFSET('Master Lists'!$N$5,0,0,COUNTA('Master Lists'!$N$5:$N$500),1)
Name L_Designation: OFFSET('Master Lists'!$O$5,0,0,COUNTA('Master Lists'!$O$5:$O$500),1)
Name L_FabricContent: OFFSET('Master Lists'!$I$5,0,0,COUNTA('Master Lists'!$I$5:$I$500),1)
Name L_FabricStage: OFFSET('Master Lists'!$U$5,0,0,COUNTA('Master Lists'!$U$5:$U$500),1)
Name L_FabricSubCat: OFFSET('Master Lists'!$F$5,0,0,COUNTA('Master Lists'!$F$5:$F$500),1)
Name L_GatePassType: OFFSET('Master Lists'!$AE$5,0,0,COUNTA('Master Lists'!$AE$5:$AE$500),1)
Name L_GRNPurpose: OFFSET('Master Lists'!$T$5,0,0,COUNTA('Master Lists'!$T$5:$T$500),1)
Name L_GSM: OFFSET('Master Lists'!$J$5,0,0,COUNTA('Master Lists'!$J$5:$J$500),1)
Name L_InformTo: OFFSET('Master Lists'!$AI$5,0,0,COUNTA('Master Lists'!$AI$5:$AI$500),1)
Name L_InspDefect26: OFFSET('Master Lists'!$AS$5,0,0,COUNTA('Master Lists'!$AS$5:$AS$500),1)
Name L_ItemCategory: OFFSET('Master Lists'!$E$5,0,0,COUNTA('Master Lists'!$E$5:$E$500),1)
Name L_Operation: OFFSET('Master Lists'!$AC$5,0,0,COUNTA('Master Lists'!$AC$5:$AC$500),1)
Name L_PaymentTerms: OFFSET('Master Lists'!$AK$5,0,0,COUNTA('Master Lists'!$AK$5:$AK$500),1)
Name L_PlanDept: OFFSET('Master Lists'!$AP$5,0,0,COUNTA('Master Lists'!$AP$5:$AP$500),1)
Name L_Process: OFFSET('Master Lists'!$R$5,0,0,COUNTA('Master Lists'!$R$5:$R$500),1)
Name L_Purpose: OFFSET('Master Lists'!$S$5,0,0,COUNTA('Master Lists'!$S$5:$S$500),1)
Name L_RejectReason: OFFSET('Master Lists'!$AJ$5,0,0,COUNTA('Master Lists'!$AJ$5:$AJ$500),1)
Name L_SentFor: OFFSET('Master Lists'!$AL$5,0,0,COUNTA('Master Lists'!$AL$5:$AL$500),1)
Name L_ShipMode: OFFSET('Master Lists'!$C$5,0,0,COUNTA('Master Lists'!$C$5:$C$500),1)
Name L_SizeGroup: OFFSET('Master Lists'!$M$5,0,0,COUNTA('Master Lists'!$M$5:$M$500),1)
Name L_StatusActive: OFFSET('Master Lists'!$Y$5,0,0,COUNTA('Master Lists'!$Y$5:$Y$500),1)
Name L_StatusApproval: OFFSET('Master Lists'!$X$5,0,0,COUNTA('Master Lists'!$X$5:$X$500),1)
Name L_StatusDispatch: OFFSET('Master Lists'!$AG$5,0,0,COUNTA('Master Lists'!$AG$5:$AG$500),1)
Name L_StatusDyeRecv: OFFSET('Master Lists'!$AO$5,0,0,COUNTA('Master Lists'!$AO$5:$AO$500),1)
Name L_StatusGatePass: OFFSET('Master Lists'!$AN$5,0,0,COUNTA('Master Lists'!$AN$5:$AN$500),1)
Name L_StatusGeneral: OFFSET('Master Lists'!$W$5,0,0,COUNTA('Master Lists'!$W$5:$W$500),1)
Name L_StatusQC: OFFSET('Master Lists'!$Z$5,0,0,COUNTA('Master Lists'!$Z$5:$Z$500),1)
Name L_StatusRecon: OFFSET('Master Lists'!$AH$5,0,0,COUNTA('Master Lists'!$AH$5:$AH$500),1)
Name L_StitchingUnit: OFFSET('Master Lists'!$P$5,0,0,COUNTA('Master Lists'!$P$5:$P$500),1)
Name L_StyleCategory: OFFSET('Master Lists'!$AB$5,0,0,COUNTA('Master Lists'!$AB$5:$AB$500),1)
Name L_UOM: OFFSET('Master Lists'!$D$5,0,0,COUNTA('Master Lists'!$D$5:$D$500),1)
Name L_VendorCategory: OFFSET('Master Lists'!$AA$5,0,0,COUNTA('Master Lists'!$AA$5:$AA$500),1)
Name L_YesNo: OFFSET('Master Lists'!$AM$5,0,0,COUNTA('Master Lists'!$AM$5:$AM$500),1)
Name M_BuyerCode: OFFSET('Buyer Master'!$A$7,0,0,COUNTA('Buyer Master'!$A$7:$A$500),1)
Name M_BuyerConsignee: OFFSET('Buyer Master'!$K$7,0,0,COUNTA('Buyer Master'!$B$7:$B$500),1)
Name M_BuyerConsigneeAddr: OFFSET('Buyer Master'!$L$7,0,0,COUNTA('Buyer Master'!$B$7:$B$500),1)
Name M_BuyerDestination: OFFSET('Buyer Master'!$O$7,0,0,COUNTA('Buyer Master'!$B$7:$B$500),1)

Sheet Master Lists
A1: Role Acess - Head Office / Admin | C1: SEKAWATI IMPEX
C2: Master Lists - all dropdown values (add new values at the bottom of a column; dropdowns update automatically)
A4: Country | B4: Currency | C4: ShipMode | D4: UOM | E4: ItemCategory | F4: FabricSubCat | G4: AccessoriesItem | H4: ColorCode | I4: FabricContent | J4: GSM | K4: Count | L4: Construction | M4: SizeGroup | N4: Department | O4: Designation | P4: StitchingUnit | Q4: ContainerNo | R4: Process | S4: Purpose | T4: GRNPurpose | U4: FabricStage | V4: DefectType | W4: StatusGeneral | X4: StatusApproval | Y4: StatusActive | Z4: StatusQC | AA4: VendorCategory | AB4: StyleCategory | AC4: Operation | AD4: AuthorisedBy | AE4: GatePassType | AF4: Decision | AG4: StatusDispatch | AH4: StatusRecon | AI4: InformTo | AJ4: RejectReason | AK4: PaymentTerms | AL4: SentFor | AM4: YesNo | AN4: StatusGatePass | AO4: StatusDyeRecv | AP4: PlanDept | AS4: InspDefect26
A5: India | B5: USD | C5: Ship | D5: Mtrs | E5: Fabric | F5: 8 oz | G5: Button | H5: Natural | I5: 100% Cotton | J5: 220 GSM | K5: 10x6 | L5: 76x28 | M5: Free Size | N5: Procurement | O5: Checker | P5: Unit 1 - Anil Kumar | Q5: CN-91 | R5: Dyeing | S5: Cutting | T5: Raw Material | U5: Before Stitching | V5: Untrimmed Thread | W5: Pending | X5: Pending | Y5: Active | Z5: Approved | AA5: Fabric | AB5: Tote Bag | AC5: Body Stitch | AD5: Dinesh Sir | AE5: Inward | AF5: Accept | AG5: Pending | AH5: Matched | AI5: Unit Incharge | AJ5: Fabric | AK5: Advance 30% + 70% on BL | AL5: Alteration | AM5: Yes | AN5: Pending | AO5: OK | AP5: Cutting | AS5: Stitch skipping
A6: USA | B6: EUR | C6: Air | D6: Kg | E6: Accessories | F6: 10 oz | G6: Zipper | H6: Night Black | I6: 100% Jute | J6: 260 GSM | K6: 12x12 | L6: 60x60 | M6: Small | N6: Planning | O6: Operator | P6: Unit 2 - Mahipal | Q6: CN-92 | R6: Printing | S6: Dyeing | T6: Dyeing | U6: After Stitching | V6: Handle Out | W6: In Progress | X6: Approved | Y6: Inactive | Z6: Rejected | AA6: Accessories | AB6: Basic Bag | AC6: Handle Attach | AD6: Vinay ji (GM) | AE6: Outward | AF6: Reject | AG6: Dispatched | AH6: Variance Found | AI6: QC Head | AJ6: Handle Out | AK6: LC 60 Days | AL6: Spot Rectification | AM6: No | AN6: Cleared | AO6: Sent to Scrutiny | AP6: Stitching | AS6: Open stitch
A7: UK | B7: GBP | C7: Road | D7: Pcs | E7: Handle | F7: 12 oz | G7: Cotton Handle | H7: Navy Blue | I7: Cotton-Poly 80:20 | J7: 280 GSM | K7: 16x12 | L7: 48x28 | M7: Medium | N7: Cutting | O7: Tailor | P7: Unit 3 - Ramesh | Q7: CN-93 | R7: Washing | S7: Printing | T7: Printing | V7: Handle Size | W7: Completed | X7: Rejected | Z7: Alteration | AA7: Dyeing | AB7: Purse | AC7: Hemming | AF7: Rework | AG7: In Transit | AI7: Supervisor | AJ7: Stitching | AK7: TT 30 Days | AL7: Scrap | AP7: Shipping | AS7: Sewing shifted / Uneven
A8: Netherlands | B8: INR | C8: Courier | D8: Roll | E8: Zipper | F8: 14 oz | G8: Jute Handle | H8: Olive Green | I8: Recycled Cotton | J8: 320 GSM | K8: 20x20 | L8: 68x38 | M8: Large | N8: Stitching | O8: Supervisor | P8: Unit 4 - Suresh | Q8: CN-94 | R8: Finishing | S8: Stitching | T8: Job Work Return | V8: Without Label | W8: On Hold | AA8: Printing | AB8: Pouch | AC8: Label Attach | AG8: Delivered | AI8: Production Manager | AJ8: Hard Stain | AK8: TT 45 Days | AS8: Sewing shifted / Gathering
A9: Germany | B9: AUD | D9: Box | E9: Label | F9: 16 oz | G9: Woven Label | H9: Burgundy | I9: Canvas Cotton | J9: 340 GSM | K9: 8x4 | M9: XL | N9: Printing | O9: Manager | Q9: CN-95 | S9: Return | T9: Accessories | V9: Slanted Label | W9: Cancelled | AA9: Stitching Unit | AB9: Shopper | AC9: Lupi Stitch | AI9: Dinesh Sir | AJ9: Dye | AK9: Net 90 | AS9: Over / Double stitch
A10: France | B10: AED | D10: Set | E10: Thread | F10: Canvas 10x6 | G10: Care Label | H10: Off White | J10: 400 GSM | N10: QC | O10: GM | S10: Sampling | V10: Double Lupi | AA10: External QC | AC10: Gusset Stitch | AS10: Yarn cutting / Uncut thread
A11: Sweden | D11: Dozen | E11: Button | F11: Canvas 12x12 | G11: Hang Tag | H11: Khaki | N11: Packing | O11: Director | S11: Other | V11: Without Lupi | AA11: Transport | AC11: Final Trim | AS11: Blind-stitch defect / Open seam
A12: Australia | E12: Packaging Material | G12: Rivet | H12: Rust | N12: Dispatch | V12: Wrong Side Lupi | AA12: Other | AS12: Pilling / Fly yarn
A13: UAE | G13: D-Ring | V13: Weaving Defect | AS13: Press
V14: Cut/Hole | AS14: Over / Doubling stitch
V15: Improper Hem | AS15: Fabric no strength / Fabric fault
V16: Double Stitch | AS16: Side stitch / Overlock
V17: Without Stitch | AS17: Colour difference / Shade
V18: Torn | AS18: Size difference
V19: Stain | AS19: Breakage / Damage / Eyelet breakage
V20: Dyeing Shade Variation | AS20: Needle hole
AS21: Thread breakage / Broken stitch
AS22: Dirt / Spot
AS23: Walking shade / Running shade
AS24: Overlock tension
AS25: Label mistake
AS26: Handle placement
AS27: Pressing mark
AS28: Oil spot / Stain
AS29: Chalk mark
AS30: Fastener opening / Closing defect

Sheet Buyer Master
A1: Role Acess - Head Office / Admin | C1: SEKAWATI IMPEX
C2: Buyer Master
A3: Come from buyer initial letters
A4: Buyer Code | B4: Buyer Name | C4: Address | D4: Country | E4: Contact Person | F4: Email | G4: Phone | H4: Currency | I4: Payment Terms | J4: Status | K4: Consignee Name | L4: Consignee Address | M4: Notify Party Name | N4: Notify Party Address | O4: Destination | P4: Port of Discharge | Q4: Final Destination | R4: Price Terms (Incoterm) | S4: Ship Mode | T4: Freight Terms
A5: Auto | B5: Manual | C5: Manual | D5: Dropdown | E5: Manual | F5: Manual | G5: Manual | H5: Dropdown | I5: Manual | J5: Dropdown | K5: Manual | L5: Manual | M5: Manual | N5: Manual | O5: Dropdown | P5: Manual | Q5: Dropdown | R5: Manual | S5: Dropdown | T5: Dropdown
A7: TWA# | B7: Trade Word | C7: 12 Harbour Road, New York | D7: USA | E7: Michael Reed | F7: michael@tradeword.com | G7: +1 212 555 0142 | H7: USD | I7: Advance 30% + 70% on BL | J7: Active | K7: Trade Works Co. Ltd | L7: 7F, Shibuya-Shinminamiguchi bldg, 3-28-13, Shibuya, Shibuya-ku, Tokyo 150-0002, Japan | M7: TRADE WORKS ASIA LIMITED | N7: 1602A-3A, Tower 6, China HK City, 33 Canton Road, Tsim Sha Tsui, Kowloon, Hong Kong | O7: Japan | P7: Tokyo | Q7: JAPAN | R7: FOB Jaipur, India | S7: Ship | T7: Collect
A8: GBL# | B8: Global Bags Ltd | C8: 45 Camden High St, London | D8: UK | E8: Sarah Whitmore | F8: sarah@globalbags.co.uk | G8: +44 20 7946 0321 | H8: GBP | I8: LC 60 Days | J8: Active | K8: Global Bags Ltd | L8: 45 Camden High St, London NW1 7JE, United Kingdom | O8: UK | P8: Tilbury | Q8: UNITED KINGDOM | R8: FOB Jaipur, India | S8: Ship | T8: Prepaid
A9: ECO# | B9: EcoCarry BV | C9: Keizersgracht 210, Amsterdam | D9: Netherlands | E9: Jan de Vries | F9: jan@ecocarry.nl | G9: +31 20 626 4471 | H9: EUR | I9: TT 30 Days | J9: Active | K9: EcoCarry BV | L9: Keizersgracht 210, 1016 DX Amsterdam, Netherlands | O9: Netherlands | P9: Rotterdam | Q9: NETHERLANDS | R9: FOB Jaipur, India | S9: Ship | T9: Collect
A10: UTI# | B10: Urban Tote Inc | C10: 880 Market St, San Francisco | D10: USA | E10: Laura Chen | F10: laura@urbantote.com | G10: +1 415 555 0198 | H10: USD | I10: TT 45 Days | J10: Active | K10: Urban Tote Inc | L10: 880 Market St, San Francisco, CA 94102, USA | O10: USA | P10: Oakland | Q10: USA | R10: FOB Jaipur, India | S10: Air | T10: Prepaid
A11: NSA# | B11: Nordic Sacks AB | C11: Sveavagen 44, Stockholm | D11: Sweden | E11: Erik Lindqvist | F11: erik@nordicsacks.se | G11: +46 8 545 1220 | H11: EUR | I11: LC 60 Days | J11: Active | K11: Nordic Sacks AB | L11: Sveavagen 44, 111 34 Stockholm, Sweden | O11: Sweden | P11: Stockholm | Q11: SWEDEN | R11: FOB Jaipur, India | S11: Ship | T11: Collect
A12: MSS# | B12: Maison Sac SARL | C12: 18 Rue de Rivoli, Paris | D12: France | E12: Claire Dubois | F12: claire@maisonsac.fr | G12: +33 1 4260 3388 | H12: EUR | I12: TT 30 Days | J12: Active | K12: Maison Sac SARL | L12: 18 Rue de Rivoli, 75004 Paris, France | O12: France | P12: Le Havre | Q12: FRANCE | R12: FOB Jaipur, India | S12: Ship | T12: Prepaid
A13: ACP# | B13: Aussie Carry Pty | C13: 7 Collins St, Melbourne | D13: Australia | E13: Tom Hargreave | F13: tom@aussiecarry.com.au | G13: +61 3 9600 2214 | H13: AUD | I13: Net 90 | J13: Inactive | K13: Aussie Carry Pty | L13: 7 Collins St, Melbourne VIC 3000, Australia | O13: Australia | P13: Melbourne | Q13: AUSTRALIA | R13: FOB Jaipur, India | S13: Ship | T13: Collect

Sheet Vendor Master
A1: Role Acess - Head Office / Admin | C1: SEKAWATI IMPEX
C2: Vendor Master
A4: Vendor Code | B4: Vendor Name | C4: Category | D4: Address | E4: GST No | F4: Contact Person | G4: Phone | H4: Email | I4: Bank Details | J4: Status | K4: Remarks
A5: Auto | B5: Manual | C5: Dropdown | D5: Manual | E5: Manual | F5: Manual | G5: Manual | H5: Manual | I5: Manual | J5: Dropdown | K5: Text
C6: Fabric/Accessories/Dyeing | J6: Active/Inactive
A7: VEN-001 | B7: Rajasthan Fabrics | C7: Fabric | D7: Plot 12, RIICO Area, Jaipur | E7: 08AABCR1234K1Z5 | F7: Suresh Agarwal | G7: +91 98290 11223 | H7: sales@rajfabrics.in | I7: HDFC 50200012345678 | J7: Active | K7: Primary canvas supplier
A8: VEN-002 | B8: Metro Accessories | C8: Accessories | D8: Shop 8, Johri Bazar, Jaipur | E8: 08AACCM5678L1Z2 | F8: Vikram Jain | G8: +91 98280 44556 | H8: info@metroacc.in | I8: ICICI 001905001234 | J8: Active | K8: Buttons, zippers, labels
A9: VEN-003 | B9: Shilpa Tex | C9: Dyeing | D9: Bagru, Jaipur - 303007 | E9: 08AADCS9012M1Z8 | F9: Ramavtar Sharma | G9: +91 94140 77889 | H9: shilpatex@gmail.com | I9: SBI 30124567890 | J9: Active | K9: 2-3% shrinkage standard
A10: VEN-004 | B10: Bagru Prints | C10: Printing | D10: Bagru Industrial Area, Jaipur | E10: 08AAECB3456N1Z4 | F10: Mahesh Chhipa | G10: +91 93140 22110 | H10: bagruprints@gmail.com | I10: PNB 0456002000123 | J10: Active | K10: Hand block + screen
A11: VEN-005 | B11: Sempax Unit 1 | C11: Printing | D11: Sitapura, Jaipur | E11: 08AAFCS7890P1Z9 | F11: Naresh Gupta | G11: +91 99280 33445 | H11: unit1@sempax.in | I11: Axis 918020034567 | J11: Active | K11: Roll printing
A12: VEN-006 | B12: Anil Kumar Stitching | C12: Stitching Unit | D12: Sanganer, Jaipur | E12: 08AAGCA2345Q1Z1 | F12: Anil Kumar | G12: +91 96490 55667 | H12: anilstitch@gmail.com | I12: BOB 04510100012345 | J12: Active | K12: Contract - paid per piece
A13: VEN-007 | B13: QualiCheck Services | C13: External QC | D13: Malviya Nagar, Jaipur | E13: 08AAHCQ6789R1Z6 | F13: Priya Nair | G13: +91 90010 88990 | H13: ops@qualicheck.in | I13: Kotak 8712345601 | J13: Active | K13: Sorts approved/rejected/alter

Sheet Employee Master
A1: Role Acess - Admin | C1: SEKAWATI IMPEX
C2: Employee Master
A4: Emp ID | B4: Emp Name | C4: Department | D4: Designation | E4: Unit / Line | F4: Status
A5: Auto | B5: Manual | C5: Dropdown | D5: Dropdown | E5: Dropdown | F5: Dropdown
C6: Procurement/Cutting/Stitching/QC/Packing/Dispatch | D6: Checker/Operator/Supervisor/Manager | F6: Active/Inactive
A7: EMP-001 | B7: Maharaj Singh | C7: Cutting | D7: Supervisor | E7: Cutting Floor | F7: Active
A8: EMP-002 | B8: Anil Kumar | C8: Stitching | D8: Supervisor | E8: Unit 1 - Anil Kumar | F8: Active
A9: EMP-003 | B9: Mahipal Yadav | C9: Stitching | D9: Supervisor | E9: Unit 2 - Mahipal | F9: Active
A10: EMP-004 | B10: Sunita Devi | C10: QC | D10: Checker | E10: QC Hall | F10: Active
A11: EMP-005 | B11: Rekha Sharma | C11: QC | D11: Checker | E11: QC Hall | F11: Active
A12: EMP-006 | B12: Vinay Sharma | C12: Planning | D12: GM | E12: Head Office | F12: Active
A13: EMP-007 | B13: Pooja Meena | C13: Packing | D13: Operator | E13: Packing Hall | F13: Active
A14: EMP-008 | B14: Ravi Prajapat | C14: Procurement | D14: Manager | E14: Head Office | F14: Active
A15: EMP-009 | B15: Dinesh Sir | C15: Procurement | D15: Director | E15: Head Office | F15: Active
A16: EMP-010 | B16: Ramesh Kumar | C16: Stitching | D16: Supervisor | E16: Unit 3 - Ramesh | F16: Active
A17: EMP-011 | B17: Suresh Meena | C17: Stitching | D17: Supervisor | E17: Unit 4 - Suresh | F17: Active

Sheet Style Master
A1: Role Acess - Head Office / Admin | C1: SEKAWATI IMPEX
C2: Style Master (BOM)
A4: Style No | B4: Style Description | C4: Buyer | D4: Category | E4: Fabric Content | F4: Avg Fabric Utilization / Pc | G4: Size Group | H4: Image Ref | I4: Status | J4: Remarks
A5: Auto | B5: Manual | C5: Dropdown | D5: Dropdown | E5: Dropdown | F5: Manual | G5: Manual | H5: Manual | I5: Dropdown | J5: Text
C6: Master - Buyer Master
A7: TR-0751-008 | B7: Tote Bag - Long Handle Canvas | C7: Trade Word | D7: Tote Bag | E7: 100% Cotton | F7: 0.85 | G7: Free Size | H7: IMG/TR0751008.jpg | I7: Active | J7: Best seller
A8: TR-0751-009 | B8: Tote Bag - Short Handle | C8: Trade Word | D8: Tote Bag | E8: 100% Cotton | F8: 0.75 | G8: Free Size | H8: IMG/TR0751009.jpg | I8: Active
A9: TR-0752-101 | B9: Shopper Bag - Gusset | C9: Global Bags Ltd | D9: Shopper | E9: Canvas Cotton | F9: 1.1 | G9: Large | H9: IMG/TR0752101.jpg | I9: Active | J9: Gusset + base board
A10: PU-0330-045 | B10: Purse Basic - Zip Top | C10: EcoCarry BV | D10: Purse | E10: Recycled Cotton | F10: 0.3 | G10: Small | H10: IMG/PU0330045.jpg | I10: Active | J10: Zipper from Metro
A11: PU-0330-046 | B11: Purse Basic - Flap | C11: EcoCarry BV | D11: Purse | E11: Recycled Cotton | F11: 0.35 | G11: Small | H11: IMG/PU0330046.jpg | I11: Active
A12: TB-0910-012 | B12: Tote Bag - Printed Panel | C12: Urban Tote Inc | D12: Tote Bag | E12: Cotton-Poly 80:20 | F12: 0.9 | G12: Medium | H12: IMG/TB0910012.jpg | I12: Active | J12: Print before stitching
A13: BS-0455-003 | B13: Basic Bag - Jute Handle | C13: Nordic Sacks AB | D13: Basic Bag | E13: 100% Jute | F13: 0.95 | G13: Free Size | H13: IMG/BS0455003.jpg | I13: Active

Sheet Order
B1: Role Acess - Merchandising Team | H1: SEKHAWATI IMPEX
H2: Order Format
A4: Order No | B4: Order Date | C4: Item Description | D4: Buyer | E4: Bill To | F4: Ship to | G4: Buyer Delivery Date | H4: Order Qty | I4: Style No | J4: Color Code | K4: Currency | L4: Ship Mode | M4: Size Group | N4: Status | O4: Remarks | P4: Excess
A5: Manual | B5: Auto | C5: Text | D5: Dropdown | E5: Auto | F5: Dropdown | G5: Manual | H5: Manual | I5: Dropdown | J5: Dropdown | K5: Dropdown | L5: Dropdown | M5: Manual | N5: Auto | O5: Manual | P5: Approval from dinesh sir
A7: B9641IS | B7: 46240 | C7: Tote Bag - Long Handle Canvas | D7: Trade Word | E7: Trade Word, New York | F7: Trade Word DC, New Jersey | G7: 46266 | H7: 5000 | I7: TR-0751-008 | J7: Natural | K7: USD | L7: Ship | M7: Free Size | N7: In Progress | O7: First shipment of season | P7: 0.02
A8: B9646IS | B8: 46241 | C8: Tote Bag - Short Handle | D8: Trade Word | E8: Trade Word, New York | F8: Trade Word DC, New Jersey | G8: 46275 | H8: 7000 | I8: TR-0751-009 | J8: Night Black | K8: USD | L8: Ship | M8: Free Size | N8: In Progress | P8: 0.02
A9: B9652IS | B9: 46244 | C9: Shopper Bag - Gusset | D9: Global Bags Ltd | E9: Global Bags, London | F9: Global Bags DC, Tilbury | G9: 46285 | H9: 4000 | I9: TR-0752-101 | J9: Olive Green | K9: GBP | L9: Ship | M9: Large | N9: In Progress | O9: Base board required | P9: 0.03
A10: B9658IS | B10: 46246 | C10: Purse Basic - Zip Top | D10: EcoCarry BV | E10: EcoCarry, Amsterdam | F10: Rotterdam Port | G10: 46290 | H10: 10000 | I10: PU-0330-045 | J10: Off White | K10: EUR | L10: Ship | M10: Small | N10: Pending | P10: 0.02
A11: B9663IS | B11: 46248 | C11: Tote Bag - Printed Panel | D11: Urban Tote Inc | E11: Urban Tote, SF | F11: Oakland DC | G11: 46300 | H11: 6000 | I11: TB-0910-012 | J11: Navy Blue | K11: USD | L11: Air | M11: Medium | N11: Pending | O11: Print before stitching | P11: 0.02
A12: B9670IS | B12: 46252 | C12: Basic Bag - Jute Handle | D12: Nordic Sacks AB | E12: Nordic Sacks, Sthlm | F12: Stockholm DC | G12: 46310 | H12: 3500 | I12: BS-0455-003 | J12: Khaki | K12: EUR | L12: Ship | M12: Free Size | N12: Pending | P12: 0.03
A13: B9675IS | B13: 46254 | C13: Purse Basic - Flap | D13: EcoCarry BV | E13: EcoCarry, Amsterdam | F13: Rotterdam Port | G13: 46315 | H13: 8000 | I13: PU-0330-046 | J13: Burgundy | K13: EUR | L13: Ship | M13: Small | N13: Pending | P13: 0.02

Sheet Planning_
A1: Role Acess - Planning Dept (Operator/GM) | F1: Shekwati Impex
E2: Cutting/Stiching/Packing/Shipping Planning Format
C4: Planning Department | F4: Dropdown
C5: Container No | F5: Manual
C6: Order No | F6: Dropdown
C7: Style No | F7: Auto- dropdown
C8: Order Qty | F8: 10000
A11: Date | B11: Deliverable Size | C11: Status | D11: Remark

Sheet Planning
A1: Role Acess - Planning Dept (Operator/GM) | F1: SEKAWATI IMPEX
A4: Order No | B4: Date | C4: Order Qty | D4: Unit | E4: Cutting Pcs alloted | F4: Container No | G4: Style No | H4: Status | I4: Remarks
A5: Dropdown | B5: Auto | C5: Auto | D5: Dropdown | E5: Manual | F5: Dropdown | G5: Dropdown | H5: Auto | I5: Text
A7: B9641IS | B7: 46246 | C7: 5000 | D7: Unit 1 - Anil Kumar | E7: 212 | F7: CN-91 | G7: TR-0751-008 | H7: Completed | I7: Cut in 2 lots
A8: B9641IS | B8: 46251 | C8: 5000 | D8: Unit 1 - Anil Kumar | E8: 246 | F8: CN-91 | G8: TR-0751-008 | H8: In Progress | I8: 2500 pcs/day
A9: B9646IS | B9: 46250 | C9: 7000 | D9: Unit 2 - Mahipal | F9: CN-92 | G9: TR-0751-009 | H9: Completed
A10: B9646IS | B10: 46254 | C10: 7000 | D10: Unit 2 - Mahipal | F10: CN-92 | G10: TR-0751-009 | H10: In Progress
A11: B9652IS | B11: 46252 | C11: 4000 | D11: Unit 3 - Ramesh | F11: CN-93 | G11: TR-0752-101 | H11: In Progress | I11: Gusset adds time
A12: B9658IS | B12: 46256 | C12: 10000 | D12: Unit 4 - Suresh | F12: CN-94 | G12: PU-0330-045 | H12: Pending | I12: High volume - split lots
A13: B9663IS | B13: 46259 | C13: 6000 | D13: Unit 1 - Anil Kumar | F13: CN-95 | G13: TB-0910-012 | H13: Pending | I13: Air shipment

Sheet Vendor Quotation-Approval
A1: Role Acess - Procurement Dept (Manager) - Approved by Dinesh Sir | C1: SEKAWATI IMPEX
C2: Vendor Quotation & Fabric Procurement Approval
A4: Quotation No | B4: Date | C4: Item | D4: Vendor Name | E4: Rate Quoted | F4: UOM | G4: Qty | H4: Amount | I4: Authorised By | J4: Authorisation Status | K4: Remarks
A5: Auto | B5: Auto | C5: Dropdown | D5: Dropdown | E5: Manual | F5: Dropdown | G5: Manual | H5: Formula | I5: Auto | J5: Dropdown | K5: Text
H6: Rate x Qty
A7: QT-001 | B7: 46238 | C7: Fabric | D7: Rajasthan Fabrics | E7: 178 | F7: Mtrs | G7: 4500 | H7: =E7*G7 -> 801000 | I7: Dinesh Sir | J7: Approved | K7: Lowest of 3 quotes
A8: QT-002 | B8: 46238 | C8: Fabric | D8: Shilpa Tex | E8: 186 | F8: Mtrs | G8: 4500 | H8: =E8*G8 -> 837000 | I8: Dinesh Sir | J8: Rejected | K8: Rate higher
A9: QT-003 | B9: 46239 | C9: Accessories | D9: Metro Accessories | E9: 12 | F9: Pcs | G9: 9000 | H9: =E9*G9 -> 108000 | I9: Dinesh Sir | J9: Approved | K9: Cotton handles
A10: QT-004 | B10: 46242 | C10: Fabric | D10: Rajasthan Fabrics | E10: 182 | F10: Mtrs | G10: 6200 | H10: =E10*G10 -> 1128400 | I10: Dinesh Sir | J10: Approved | K10: For B9646IS
A11: QT-005 | B11: 46243 | C11: Accessories | D11: Metro Accessories | E11: 4 | F11: Pcs | G11: 12000 | H11: =E11*G11 -> 48000 | I11: Dinesh Sir | J11: Pending | K11: Zippers - awaiting sample
A12: QT-006 | B12: 46245 | C12: Fabric | D12: Rajasthan Fabrics | E12: 165 | F12: Mtrs | G12: 3400 | H12: =E12*G12 -> 561000 | I12: Dinesh Sir | J12: Approved | K12: Recycled cotton
A13: QT-007 | B13: 46247 | C13: Label | D13: Metro Accessories | E13: 3 | F13: Pcs | G13: 20000 | H13: =E13*G13 -> 60000 | I13: Dinesh Sir | J13: Approved | K13: Woven labels

Sheet PO
A1: Role Acess - Procurement Dept (Manager) | G1: SEKAWATI IMPEX
G2: PO Format
A3: Vendor initial + no
A4: PO ID | B4: Date | C4: Item | D4: sub - category | E4: Accessories item | F4: Excess Allowed | G4: Vender Name | H4: Address | I4: UOM | J4: Order Qty | K4: Rate | L4: Amount | M4: HSN Code | N4: GSM | O4: Content | P4: Color code | Q4: Count | R4: Status | S4: Remarks
A5: Auto | B5: Auto | C5: Dropdown | D5: Dropdown | G5: Dropdown | H5: Auto | I5: Dropdown | J5: Manual | K5: Manual | L5: Auto | M5: Manual | N5: Dropdown | O5: Text | P5: Dropdown | Q5: Manual | R5: Dropdown | S5: Text
C6: Master | E6: it will appear only if they selectthey will select accessory | F6: 2-3% | G6: Master | I6: Master | N6: Master | P6: Master
A7: RF-001 | B7: 46239 | C7: Fabric | D7: 10 oz | F7: 0.02 | G7: Rajasthan Fabrics | H7: RIICO Area, Jaipur | I7: Mtrs | J7: 4500 | K7: 178 | L7: =J7*K7 -> 801000 | M7: 52081290 | N7: 320 GSM | O7: 100% Cotton | P7: Natural | Q7: 10x6 | R7: Completed | S7: Order as per Style - B9641IS
A8: RF-002 | B8: 46242 | C8: Fabric | D8: 12 oz | F8: 0.02 | G8: Rajasthan Fabrics | H8: RIICO Area, Jaipur | I8: Mtrs | J8: 6200 | K8: 182 | L8: =J8*K8 -> 1128400 | M8: 52081290 | N8: 340 GSM | O8: 100% Cotton | P8: Night Black | Q8: 12x12 | R8: Completed | S8: Bulk Order - B9646IS
A9: MA-001 | B9: 46243 | C9: Accessories | E9: Cotton Handle | F9: 0.01 | G9: Metro Accessories | H9: Johri Bazar, Jaipur | I9: Pcs | J9: 9000 | K9: 12 | L9: =J9*K9 -> 108000 | M9: 63079090 | P9: Natural | R9: Completed | S9: 1% excess allowed
A10: RF-003 | B10: 46245 | C10: Fabric | D10: 10 oz | F10: 0.03 | G10: Rajasthan Fabrics | H10: RIICO Area, Jaipur | I10: Mtrs | J10: 3400 | K10: 165 | L10: =J10*K10 -> 561000 | M10: 52081290 | N10: 280 GSM | O10: Recycled Cotton | P10: Off White | Q10: 10x6 | R10: In Progress | S10: For B9658IS purses
A11: MA-002 | B11: 46247 | C11: Accessories | E11: Woven Label | F11: 0.01 | G11: Metro Accessories | H11: Johri Bazar, Jaipur | I11: Pcs | J11: 20000 | K11: 3 | L11: =J11*K11 -> 60000 | M11: 58071010 | R11: In Progress | S11: Buyer branded
A12: RF-004 | B12: 46249 | C12: Fabric | D12: 12 oz | F12: 0.02 | G12: Rajasthan Fabrics | H12: RIICO Area, Jaipur | I12: Mtrs | J12: 5600 | K12: 188 | L12: =J12*K12 -> 1052800 | M12: 52081290 | N12: 340 GSM | O12: Cotton-Poly 80:20 | P12: Navy Blue | Q12: 12x12 | R12: Pending | S12: Bulk Order - B9663IS
A13: MA-003 | B13: 46250 | C13: Accessories | E13: Zipper | F13: 0.01 | G13: Metro Accessories | H13: Johri Bazar, Jaipur | I13: Pcs | J13: 12000 | K13: 4 | L13: =J13*K13 -> 48000 | M13: 96071110 | P13: Off White | R13: Pending | S13: Awaiting quote approval

Sheet Gate Pass
A1: Role Acess - Procurement Dept (Checker) | C1: SEKAWATI IMPEX
C2: Gate Pass (Inward / Outward)
A4: Gate Pass No | B4: Date | C4: Type | D4: Linked PO / Challan No | E4: Item | F4: Vendor / Unit Name | G4: Qty | H4: Received Qty | I4: Variation % | J4: UOM | K4: Purpose | L4: Authorised By | M4: Status | N4: Remarks
A5: Auto | B5: Auto | C5: Dropdown | D5: Dropdown | E5: Dropdown | F5: Dropdown | G5: Auto | H5: Manual | I5: Auto | J5: Auto | K5: Dropdown | L5: Auto | M5: Dropdown | N5: Text
C6: Inward/Outward | K6: Dyeing/Printing/Stitching/Other | L6: By name | M6: Pending/Cleared
A7: GP-001 | B7: 46243 | C7: Inward | D7: RF-001 | E7: Fabric | F7: Rajasthan Fabrics | G7: 4500 | H7: 4500 | I7: =IFERROR((G7-H7)/G7,0) -> 0 | J7: Mtrs | K7: Other | L7: Ravi Prajapat | M7: Cleared | N7: Against PO RF-001
A8: GP-002 | B8: 46244 | C8: Outward | D8: DY-001 | E8: Fabric | F8: Shilpa Tex | G8: 2000 | H8: 2000 | I8: =IFERROR((G8-H8)/G8,0) -> 0 | J8: Mtrs | K8: Dyeing | L8: Dinesh Sir | M8: Cleared | N8: Sent for dyeing
A9: GP-003 | B9: 46248 | C9: Inward | D9: DY-001 | E9: Dyed Fabric | F9: Shilpa Tex | G9: 2000 | H9: 1950 | I9: =IFERROR((G9-H9)/G9,0) -> 0.025 | J9: Mtrs | K9: Dyeing | L9: Ravi Prajapat | M9: Cleared | N9: 2.5% shrinkage
A10: GP-004 | B10: 46249 | C10: Outward | D10: PR-001 | E10: Cut Panels | F10: Bagru Prints | G10: 3000 | H10: 3000 | I10: =IFERROR((G10-H10)/G10,0) -> 0 | J10: Pcs | K10: Printing | L10: Dinesh Sir | M10: Cleared | N10: Print before stitching
A11: GP-005 | B11: 46251 | C11: Outward | D11: CH-001 | E11: Cutting Pieces | F11: Anil Kumar Stitching | G11: 2500 | H11: 2500 | I11: =IFERROR((G11-H11)/G11,0) -> 0 | J11: Pcs | K11: Stitching | L11: Ravi Prajapat | M11: Cleared | N11: Unit 1 allotment
A12: GP-006 | B12: 46253 | C12: Inward | D12: CH-001 | E12: Cutting Pieces | F12: Anil Kumar Stitching | G12: 2500 | H12: 2460 | I12: =IFERROR((G12-H12)/G12,0) -> 0.016 | J12: Pcs | K12: Stitching | L12: Ravi Prajapat | M12: Cleared | N12: 40 pcs held for alteration
A13: GP-007 | B13: 46255 | C13: Inward | D13: MA-003 | E13: Zipper | F13: Metro Accessories | G13: 12000 | H13: 12000 | I13: =IFERROR((G13-H13)/G13,0) -> 0 | J13: Pcs | K13: Other | L13: Ravi Prajapat | M13: Pending | N13: Awaiting QC count

Sheet GRN
A1: Role Acess - Procurement Dept (Checker) | I1: SEKAWATI IMPEX
I2: GRNFormat
A4: PO ID | B4: Bill No | C4: Roll No | D4: Date | E4: purpose | F4: Item | G4: HSN Code | H4: Vender | I4: UOM | J4: Order Qty | K4: Receiving Qty | L4: Inventory Rate | M4: Amount | N4: Status | O4: Remarks
A5: Dropdown | B5: Manual | C5: Manual | D5: Auto | E5: Dropdown | F5: Auto | G5: Auto | H5: Auto | I5: Auto | J5: Auto | K5: Manual | L5: Formula | M5: Auto | N5: Dropdown | O5: Text
A7: RF-001 | B7: BL-1201 | D7: 46243 | E7: Raw Material | F7: Fabric | G7: 52081290 | H7: Rajasthan Fabrics | I7: Mtrs | J7: 4500 | K7: 4500 | L7: 178 | M7: =K7*L7 -> 801000 | N7: Completed | O7: Full qty received
A8: RF-002 | B8: BL-1215 | D8: 46246 | E8: Raw Material | F8: Fabric | G8: 52081290 | H8: Rajasthan Fabrics | I8: Mtrs | J8: 6200 | K8: 6180 | L8: 182 | M8: =K8*L8 -> 1124760 | N8: Completed | O8: 20 mtrs short
A9: MA-001 | B9: MA-0450 | D9: 46247 | E9: Accessories | F9: Accessories | G9: 63079090 | H9: Metro Accessories | I9: Pcs | J9: 9000 | K9: 9090 | L9: 12 | M9: =K9*L9 -> 109080 | N9: Completed | O9: Cotton Handle - 1% excess received
A10: RF-003 | B10: BL-1233 | D10: 46250 | E10: Raw Material | F10: Fabric | G10: 52081290 | H10: Rajasthan Fabrics | I10: Mtrs | J10: 3400 | K10: 3400 | L10: 165 | M10: =K10*L10 -> 561000 | N10: Completed
A11: MA-002 | B11: MA-0461 | D11: 46252 | E11: Accessories | F11: Accessories | G11: 58071010 | H11: Metro Accessories | I11: Pcs | J11: 20000 | K11: 20000 | L11: 3 | M11: =K11*L11 -> 60000 | N11: Completed | O11: Woven Label - buyer branded
A12: RF-004 | B12: BL-1247 | D12: 46254 | E12: Raw Material | F12: Fabric | G12: 52081290 | H12: Rajasthan Fabrics | I12: Mtrs | J12: 5600 | K12: 2800 | L12: 188 | M12: =K12*L12 -> 526400 | N12: In Progress | O12: Partial - balance in transit
A13: MA-003 | B13: MA-0470 | D13: 46256 | E13: Accessories | F13: Zipper | G13: 96071110 | H13: Metro Accessories | I13: Pcs | J13: 12000 | K13: 12000 | L13: 4 | M13: =K13*L13 -> 48000 | N13: Completed

Sheet Fabric Issue
A1: Role Acess - Cutting Dept (Supervisor) | F1: SEKAWATI IMPEX
F2: Fabric Issue for Cutting Format
A4: Date | B4: Vendor | C4: Roll No | D4: Purpose | E4: Order No | F4: Style No | G4: Name | H4: Fabric Qty Issued | I4: Fabric name | J4: Color Code | K4: Status | L4: Remarks
A5: Auto | C5: Manual | D5: Dropdown | E5: Dropdown | F5: Dropdown | G5: Auto | H5: Manual | I5: Dropdown | J5: Dropdown | K5: Auto | L5: Text
I6: eg- 10 oz
A7: 46244 | C7: FAB-001 | D7: Dyeing | E7: B9641IS | F7: TR-0751-008 | G7: Maharaj Singh | H7: 2000 | I7: 10 oz 10x6 | J7: Natural | K7: Completed | L7: Sent to Shilpa Tex
A8: 46248 | C8: FAB-002 | D8: Cutting | E8: B9641IS | F8: TR-0751-008 | G8: Maharaj Singh | H8: 1950 | I8: 10 oz 10x6 | J8: Natural | K8: Completed | L8: Post dyeing
A9: 46249 | C9: FAB-003 | D9: Printing | E9: B9663IS | F9: TB-0910-012 | G9: Maharaj Singh | H9: 1200 | I9: 12 oz 12x12 | J9: Navy Blue | K9: In Progress | L9: Panel print
A10: 46250 | C10: FAB-004 | D10: Cutting | E10: B9646IS | F10: TR-0751-009 | G10: Maharaj Singh | H10: 3000 | I10: 12 oz 12x12 | J10: Night Black | K10: Completed
A11: 46252 | C11: FAB-005 | D11: Cutting | E11: B9652IS | F11: TR-0752-101 | G11: Maharaj Singh | H11: 2200 | I11: 10 oz 10x6 | J11: Olive Green | K11: Completed | L11: Gusset panels
A12: 46253 | C12: FAB-006 | D12: Dyeing | E12: B9658IS | F12: PU-0330-045 | G12: Maharaj Singh | H12: 1500 | I12: 10 oz 10x6 | J12: Off White | K12: In Progress
A13: 46255 | C13: FAB-007 | D13: Cutting | E13: B9670IS | F13: BS-0455-003 | G13: Maharaj Singh | H13: 1100 | I13: Jute Canvas | J13: Khaki | K13: Pending
A14: 46257 | C14: FAB-008 | D14: Dyeing | E14: B9675IS | F14: PU-0330-046 | G14: Maharaj Singh | H14: 1800 | I14: 10 oz 10x6 | J14: Burgundy | K14: In Progress
A15: 46259 | C15: FAB-009 | D15: Dyeing | E15: B9663IS | F15: TB-0910-012 | G15: Maharaj Singh | H15: 2500 | I15: 12 oz 12x12 | J15: Navy Blue | K15: In Progress | L15: Shade issue reported
A16: 46261 | C16: FAB-010 | D16: Cutting | E16: B9670IS | F16: BS-0455-003 | G16: Maharaj Singh | H16: 1600 | I16: Jute Canvas | J16: Khaki | K16: Pending

Sheet Dye issue
A1: Role Acess - Procurement Dept (Checker) | J1: SEKAWATI IMPEX
J2: Dye Format
A5: Date | B5: Process | C5: Roll No | D5: Colour Code | E5: Content | F5: Count | G5: Construction | H5: Width | I5: GSM | J5: Vendor Name | K5: Address | L5: Pin Code | M5: Qty | N5: UOM | O5: Rate | P5: Amount | Q5: Remark
A6: Auto | B6: Manual | C6: Auto-Dropdown | D6: Auto-Dropdown | E6: Manual | F6: Manual | G6: Manual | H6: Manual | I6: Manual | J6: Auto-Dropdown | K6: Text | L6: Number | M6: Manual | N6: Auto | O6: Manual | P6: Auto | Q6: Text
A8: 46244 | B8: Dyeing | C8: FAB-001 | D8: Natural | E8: 100% Cotton | F8: 10x6 | G8: 76x28 | H8: 63 | I8: 320 GSM | J8: Shilpa Tex | K8: Bagru, Jaipur | L8: 303007 | M8: 2000 | N8: Mtrs | O8: 42 | P8: =M8*O8 -> 84000 | Q8: PO DY-001
A9: 46246 | B9: Dyeing | C9: FAB-004 | D9: Night Black | E9: 100% Cotton | F9: 12x12 | G9: 60x60 | H9: 63 | I9: 340 GSM | J9: Shilpa Tex | K9: Bagru, Jaipur | L9: 303007 | M9: 3000 | N9: Mtrs | O9: 45 | P9: =M9*O9 -> 135000 | Q9: PO DY-002
A10: 46249 | B10: Printing | C10: FAB-003 | D10: Navy Blue | E10: Cotton-Poly 80:20 | F10: 12x12 | G10: 60x60 | H10: 63 | I10: 340 GSM | J10: Bagru Prints | K10: Bagru, Jaipur | L10: 303007 | M10: 1200 | N10: Mtrs | O10: 38 | P10: =M10*O10 -> 45600 | Q10: Panel print
A11: 46251 | B11: Dyeing | C11: FAB-005 | D11: Olive Green | E11: Canvas Cotton | F11: 10x6 | G11: 76x28 | H11: 60 | I11: 280 GSM | J11: Shilpa Tex | K11: Bagru, Jaipur | L11: 303007 | M11: 2200 | N11: Mtrs | O11: 44 | P11: =M11*O11 -> 96800 | Q11: PO DY-003
A12: 46253 | B12: Dyeing | C12: FAB-006 | D12: Off White | E12: Recycled Cotton | F12: 10x6 | G12: 48x28 | H12: 58 | I12: 260 GSM | J12: Shilpa Tex | K12: Bagru, Jaipur | L12: 303007 | M12: 1500 | N12: Mtrs | O12: 40 | P12: =M12*O12 -> 60000 | Q12: PO DY-004
A13: 46255 | B13: Printing | C13: FAB-007 | D13: Khaki | E13: 100% Jute | F13: 8x4 | G13: 68x38 | H13: 60 | I13: 400 GSM | J13: Sempax Unit 1 | K13: Sitapura, Jaipur | L13: 302022 | M13: 1100 | N13: Mtrs | O13: 36 | P13: =M13*O13 -> 39600 | Q13: Roll printing
A14: 46257 | B14: Dyeing | C14: FAB-008 | D14: Burgundy | E14: Recycled Cotton | F14: 10x6 | G14: 48x28 | H14: 58 | I14: 260 GSM | J14: Shilpa Tex | K14: Bagru, Jaipur | L14: 303007 | M14: 1800 | N14: Mtrs | O14: 41 | P14: =M14*O14 -> 73800 | Q14: PO DY-005

Sheet Fabric Scrutiny Report
A1: Role Acess - QC Dept - Decision by Dinesh Sir | C1: SEKAWATI IMPEX
C2: Fabric Scrutiny Report
A4: Date | B4: Fabric No | C4: Order No | D4: Style No | E4: Defect Type | F4: Qty Affected | G4: Checked By | H4: Authorised By | I4: Decision | J4: Remarks
A5: Auto | B5: Dropdown | C5: Dropdown | D5: Dropdown | E5: Dropdown | F5: Manual | G5: Dropdown | H5: Dropdown | I5: Dropdown | J5: Text
E6: Dyeing Defect/Weaving Defect | G6: Master - Employee | H6: Dinesh Sir | I6: Accept/Reject/Rework
A7: 46252 | B7: FAB-005 | C7: B9652IS | D7: TR-0752-101 | E7: Dyeing Shade Variation | F7: 110 | G7: Sunita Devi | H7: Dinesh Sir | I7: Rework | J7: Re-dye at vendor cost
A8: 46253 | B8: FAB-005 | C8: B9652IS | D8: TR-0752-101 | E8: Weaving Defect | F8: 40 | G8: Rekha Sharma | H8: Dinesh Sir | I8: Reject | J8: Debit note to vendor
A9: 46260 | B9: FAB-009 | C9: B9663IS | D9: TB-0910-012 | E9: Dyeing Shade Variation | F9: 150 | G9: Sunita Devi | H9: Dinesh Sir | I9: Rework | J9: Shade card mismatch
A10: 46261 | B10: FAB-009 | C10: B9663IS | D10: TB-0910-012 | E10: Cut/Hole | F10: 25 | G10: Rekha Sharma | H10: Dinesh Sir | I10: Reject | J10: Loom damage
A11: 46263 | B11: FAB-002 | C11: B9641IS | D11: TR-0751-008 | E11: Stain | F11: 18 | G11: Sunita Devi | H11: Dinesh Sir | I11: Accept | J11: Washable - accepted
A12: 46264 | B12: FAB-006 | C12: B9658IS | D12: PU-0330-045 | E12: Weaving Defect | F12: 32 | G12: Rekha Sharma | H12: Dinesh Sir | I12: Rework | J12: Panel re-cut possible
A13: 46265 | B13: FAB-008 | C13: B9675IS | D13: PU-0330-046 | E13: Dyeing Shade Variation | F13: 60 | G13: Sunita Devi | H13: Dinesh Sir | I13: Accept | J13: Within buyer tolerance

Sheet Printing
A1: Role Acess - Printing Dept (Manager) | D1: SEKAWATI IMPEX
D2: Printing Format
A3: Date | B3: Order No | C3: Style No. | D3: Vendor | E3: Fabric Stage | F3: Qty | G3: UOM | H3: Remarks
A4: Auto | B4: Auto | C4: Auto | D4: Dropdown | E4: Dropdown | F4: Manual | G4: Dropdown | H4: text
A6: 46249 | B6: B9663IS | C6: TB-0910-012 | D6: Bagru Prints | E6: Before Stitching | F6: 1200 | G6: Roll | H6: Panel print - 2 colour
A7: 46251 | B7: B9663IS | C7: TB-0910-012 | D7: Bagru Prints | E7: Before Stitching | F7: 800 | G7: Roll | H7: Second lot
A8: 46255 | B8: B9670IS | C8: BS-0455-003 | D8: Sempax Unit 1 | E8: Before Stitching | F8: 1100 | G8: Roll | H8: Roll printing
A9: 46258 | B9: B9641IS | C9: TR-0751-008 | D9: Bagru Prints | E9: After Stitching | F9: 500 | G9: Pcs | H9: Logo print on finished bag
A10: 46260 | B10: B9646IS | C10: TR-0751-009 | D10: Bagru Prints | E10: After Stitching | F10: 750 | G10: Pcs | H10: Buyer logo
A11: 46262 | B11: B9652IS | C11: TR-0752-101 | D11: Sempax Unit 1 | E11: Before Stitching | F11: 900 | G11: Roll
A12: 46264 | B12: B9675IS | C12: PU-0330-046 | D12: Bagru Prints | E12: After Stitching | F12: 400 | G12: Pcs | H12: Small flap print

Sheet  Plan Approval
A1: Role Acess - Planning Dept - Approved by Vinay ji (GM) / Dinesh Sir | C1: SEKAWATI IMPEX
C2: Cutting / Stitching / Shipping Plan Approval Log
A4: Date | B4: Order No | C4: Container No | D4: Prepared By | E4: Submitted To | F4: Approval Status | G4: Rejection Reason | H4: Rectification Remarks | I4: Approved Date
A5: Auto | B5: Auto | C5: Auto | D5: Auto | E5: Auto | F5: Auto | G5: Text | H5: Text | I5: Auto
E6: Vinay ji (GM) | F6: Dinesh Sir | G6: Pending/Approved/Rejected
A7: 46245 | B7: B9641IS | C7: CN-91 | D7: Vinay ji (GM) | E7: Dinesh Sir | F7: Approved | I7: 46246
A8: 46249 | B8: B9646IS | C8: CN-92 | D8: Vinay ji (GM) | E8: Dinesh Sir | F8: Approved | I8: 46250
A9: 46251 | B9: B9652IS | C9: CN-93 | D9: Vinay ji (GM) | E9: Dinesh Sir | F9: Rejected | G9: Unit 3 overloaded | H9: Shift 1500 pcs to Unit 4
A10: 46252 | B10: B9652IS | C10: CN-93 | D10: Vinay ji (GM) | E10: Dinesh Sir | F10: Approved | H10: Revised plan v2 | I10: 46252
A11: 46255 | B11: B9658IS | C11: CN-94 | D11: Vinay ji (GM) | E11: Dinesh Sir | F11: Rejected | G11: Shipping date too tight | H11: Extend cutting by 3 days
A12: 46256 | B12: B9658IS | C12: CN-94 | D12: Vinay ji (GM) | E12: Dinesh Sir | F12: Approved | H12: Revised plan v2 | I12: 46257
A13: 46258 | B13: B9663IS | C13: CN-95 | D13: Vinay ji (GM) | E13: Dinesh Sir | F13: Pending | H13: Awaiting fabric scrutiny

Sheet Cutting Issue
A1: Role Acess - Cutting Dept (Tailor/Supervisor) | F1: SEKAWATI IMPEX
F2: Cutting Format
A4: Date | B4: Challan No | C4: Order No | D4: Style No | E4: Planned Cutting | F4: Firm Name | G4: Unit wise Cutting Pcs to be issued | H4: Cutting Pcs Issued | I4: Handle issued | J4: Container No | K4: Status | L4: Remarks
A5: Auto | B5: Manual | C5: Auto | D5: Auto | E5: Auto | F5: Auto | G5: Auto | H5: Manual | I5: Manual | J5: Formula | K5: Dropdown | L5: Text
J6: From Planning (via Order No)
A7: 46247 | B7: CH-001 | C7: B9641IS | D7: TR-0751-008 | E7: 5000 | F7: Unit 1 - Anil Kumar | G7: 2500 | H7: 2500 | I7: 2500 | J7: =IFERROR(INDEX(Planning!$F$7:$F$500,MATCH($C7,Planning!$A$7:$A$500,0)),"") -> CN-91 | K7: Completed | L7: Lot 1
A8: 46248 | B8: CH-002 | C8: B9641IS | D8: TR-0751-008 | E8: 5000 | F8: Unit 1 - Anil Kumar | G8: 2500 | H8: 2500 | I8: 2500 | J8: =IFERROR(INDEX(Planning!$F$7:$F$500,MATCH($C8,Planning!$A$7:$A$500,0)),"") -> CN-91 | K8: Completed | L8: Lot 2
A9: 46250 | B9: CH-003 | C9: B9646IS | D9: TR-0751-009 | E9: 7000 | F9: Unit 2 - Mahipal | G9: 3500 | H9: 3500 | I9: 3500 | J9: =IFERROR(INDEX(Planning!$F$7:$F$500,MATCH($C9,Planning!$A$7:$A$500,0)),"") -> CN-92 | K9: Completed | L9: Lot 1
A10: 46252 | B10: CH-004 | C10: B9646IS | D10: TR-0751-009 | E10: 7000 | F10: Unit 2 - Mahipal | G10: 3500 | H10: 3500 | I10: 3500 | J10: =IFERROR(INDEX(Planning!$F$7:$F$500,MATCH($C10,Planning!$A$7:$A$500,0)),"") -> CN-92 | K10: In Progress | L10: Lot 2
A11: 46253 | B11: CH-005 | C11: B9652IS | D11: TR-0752-101 | E11: 4000 | F11: Unit 3 - Ramesh | G11: 2000 | H11: 2000 | I11: 2000 | J11: =IFERROR(INDEX(Planning!$F$7:$F$500,MATCH($C11,Planning!$A$7:$A$500,0)),"") -> CN-93 | K11: In Progress | L11: Gusset panels separate
A12: 46256 | B12: CH-006 | C12: B9658IS | D12: PU-0330-045 | E12: 10000 | F12: Unit 4 - Suresh | G12: 5000 | H12: 5000 | I12: 5000 | J12: =IFERROR(INDEX(Planning!$F$7:$F$500,MATCH($C12,Planning!$A$7:$A$500,0)),"") -> CN-94 | K12: In Progress | L12: Lot 1 of 2
A13: 46259 | B13: CH-007 | C13: B9663IS | D13: TB-0910-012 | E13: 6000 | F13: Unit 1 - Anil Kumar | G13: 3000 | H13: 3000 | I13: 3000 | J13: =IFERROR(INDEX(Planning!$F$7:$F$500,MATCH($C13,Planning!$A$7:$A$500,0)),"") -> CN-95 | K13: Pending | L13: Printed panels

Sheet Stiching Record
A1: Role Acess - Stitching Dept (Supervisor) | D1: SEKAWATI IMPEX
D2: Stiching Record Format
A4: Unit Name | B4: Date | C4: Order No | D4: Style No | E4: Deliverable Size | F4: Actual | G4: Remaining | H4: Remarks
A5: Auto | B5: Auto | C5: Auto | D5: Auto | E5: Auto | F5: Manual | G5: Auto | H5: Text
A7: Unit 1 - Anil Kumar | B7: 46251 | C7: B9641IS | D7: TR-0751-008 | E7: 2500 | F7: 2380 | G7: =E7-F7 -> 120 | H7: 120 pcs to alteration
A8: Unit 1 - Anil Kumar | B8: 46252 | C8: B9641IS | D8: TR-0751-008 | E8: 2500 | F8: 2450 | G8: =E8-F8 -> 50
A9: Unit 2 - Mahipal | B9: 46254 | C9: B9646IS | D9: TR-0751-009 | E9: 3500 | F9: 3320 | G9: =E9-F9 -> 180 | H9: Handle attach delay
A10: Unit 2 - Mahipal | B10: 46256 | C10: B9646IS | D10: TR-0751-009 | E10: 3500 | F10: 3410 | G10: =E10-F10 -> 90
A11: Unit 3 - Ramesh | B11: 46257 | C11: B9652IS | D11: TR-0752-101 | E11: 2000 | F11: 1860 | G11: =E11-F11 -> 140 | H11: Gusset slows line
A12: Unit 4 - Suresh | B12: 46259 | C12: B9658IS | D12: PU-0330-045 | E12: 5000 | F12: 4780 | G12: =E12-F12 -> 220 | H12: Purse - high output
A13: Unit 1 - Anil Kumar | B13: 46261 | C13: B9663IS | D13: TB-0910-012 | E13: 3000 | F13: 2890 | G13: =E13-F13 -> 110 | H13: Printed panel alignment

Sheet Hourly Monitoring
A1: Role Acess - Stitching Dept (Supervisor) | F1: SEKAWATI IMPEX
F2: Stitching Hourly Format
A4: Date | B4: order No | C4: Emp Id | D4: 10 | E4: 11 | F4: 12 | G4: 1 | H4: 2 | I4: 3 | J4: 4 | K4: 5;30 | L4: 0.27083333
A5: Auto Capture | B5: Auto | C5: Dropdown | D5: Manual | E5: Manual | F5: Manual | G5: Manual | H5: Manual | I5: Manual | J5: Manual | K5: Manual | L5: Manual
D6: TIME AUTO CAPTURE
A7: 46251 | B7: B9641IS | C7: EMP-002 | D7: 42 | E7: 45 | F7: 40 | G7: 38 | H7: 44 | I7: 46 | J7: 43 | K7: 40 | L7: 35
A8: 46252 | B8: B9641IS | C8: EMP-002 | D8: 44 | E8: 46 | F8: 43 | G8: 40 | H8: 45 | I8: 47 | J8: 44 | K8: 42 | L8: 36
A9: 46254 | B9: B9646IS | C9: EMP-003 | D9: 38 | E9: 41 | F9: 39 | G9: 36 | H9: 40 | I9: 42 | J9: 41 | K9: 38 | L9: 33
A10: 46256 | B10: B9646IS | C10: EMP-003 | D10: 40 | E10: 43 | F10: 41 | G10: 38 | H10: 42 | I10: 44 | J10: 42 | K10: 40 | L10: 34
A11: 46257 | B11: B9652IS | C11: EMP-002 | D11: 30 | E11: 33 | F11: 31 | G11: 29 | H11: 32 | I11: 34 | J11: 33 | K11: 31 | L11: 27
A12: 46259 | B12: B9658IS | C12: EMP-003 | D12: 55 | E12: 58 | F12: 56 | G12: 52 | H12: 57 | I12: 59 | J12: 56 | K12: 54 | L12: 48
A13: 46261 | B13: B9663IS | C13: EMP-002 | D13: 41 | E13: 44 | F13: 42 | G13: 39 | H13: 43 | I13: 45 | J13: 43 | K13: 41 | L13: 35

Sheet QC Size
A1: Role Acess - QC Dept (Checker) | D1: SEKAWATI IMPEX
D2: Daily QC Record (Tailor Size)
A4: Date | B4: Order No | C4: Unit | D4: Tailor Name | E4: Style No | F4: Operation | G4: Size | H4: Psc Checked/Reject | I4: Defects found | J4: Inform To
A5: Auto | B5: Dropdown | C5: Dropdown | D5: Dropdown | E5: Dropdown | F5: Dropdown | G5: Manual | H5: Manual | I5: Dropdown | J5: Dropdown
A7: 46251 | B7: B9641IS | C7: Unit 1 - Anil Kumar | D7: Anil Kumar | E7: TR-0751-008 | F7: Handle Attach | G7: Free Size | H7: 200 | I7: Handle Size | J7: Unit Incharge
A8: 46252 | B8: B9641IS | C8: Unit 1 - Anil Kumar | D8: Anil Kumar | E8: TR-0751-008 | F8: Body Stitch | G8: Free Size | H8: 180 | I8: Improper Hem | J8: Supervisor
A9: 46254 | B9: B9646IS | C9: Unit 2 - Mahipal | D9: Mahipal Yadav | E9: TR-0751-009 | F9: Hemming | G9: Free Size | H9: 220 | I9: Untrimmed Thread | J9: Unit Incharge
A10: 46256 | B10: B9646IS | C10: Unit 2 - Mahipal | D10: Mahipal Yadav | E10: TR-0751-009 | F10: Label Attach | G10: Free Size | H10: 150 | I10: Slanted Label | J10: QC Head
A11: 46257 | B11: B9652IS | C11: Unit 3 - Ramesh | D11: Ramesh Kumar | E11: TR-0752-101 | F11: Gusset Stitch | G11: Large | H11: 190 | I11: Without Stitch | J11: Production Manager
A12: 46259 | B12: B9658IS | C12: Unit 4 - Suresh | D12: Suresh Meena | E12: PU-0330-045 | F12: Body Stitch | G12: Small | H12: 260 | I12: Double Stitch | J12: Supervisor
A13: 46261 | B13: B9663IS | C13: Unit 1 - Anil Kumar | D13: Anil Kumar | E13: TB-0910-012 | F13: Lupi Stitch | G13: Medium | H13: 170 | I13: Wrong Side Lupi | J13: QC Head

Sheet QC Defects
A1: Role Acess - QC Dept (Checker) | C1: SEKAWATI IMPEX
C2: Daily QC Record (Tailor Defects)
A4: Date | B4: Order No | C4: Unit | D4: Tailor Name | E4: Style | F4: Pcs Checked/Reject | G4: Defects Found | H4: Inform To
A5: Auto | B5: Dropdown | C5: Dropdown | D5: Dropdown | E5: Dropdown | F5: Manual | G5: Dropdown | H5: Dropdown
A7: 46251 | B7: B9641IS | C7: Unit 1 - Anil Kumar | D7: Anil Kumar | E7: TR-0751-008 | F7: 24 | G7: Handle Out | H7: Unit Incharge
A8: 46252 | B8: B9641IS | C8: Unit 1 - Anil Kumar | D8: Anil Kumar | E8: TR-0751-008 | F8: 18 | G8: Untrimmed Thread | H8: Supervisor
A9: 46254 | B9: B9646IS | C9: Unit 2 - Mahipal | D9: Mahipal Yadav | E9: TR-0751-009 | F9: 31 | G9: Improper Hem | H9: Unit Incharge
A10: 46256 | B10: B9646IS | C10: Unit 2 - Mahipal | D10: Mahipal Yadav | E10: TR-0751-009 | F10: 15 | G10: Without Label | H10: QC Head
A11: 46257 | B11: B9652IS | C11: Unit 3 - Ramesh | D11: Ramesh Kumar | E11: TR-0752-101 | F11: 27 | G11: Double Stitch | H11: Production Manager
A12: 46259 | B12: B9658IS | C12: Unit 4 - Suresh | D12: Suresh Meena | E12: PU-0330-045 | F12: 42 | G12: Stain | H12: Supervisor
A13: 46261 | B13: B9663IS | C13: Unit 1 - Anil Kumar | D13: Anil Kumar | E13: TB-0910-012 | F13: 22 | G13: Cut/Hole | H13: QC Head

Sheet Internal Quality Check
A1: Role Acess - QC Dept (Checker) | C1: SEKAWATI IMPEX
C2: Internal Quality Check (Finishing & Trimming) Hourly basis
A4: Date | B4: Order No | C4: Style No | D4: Stitching Unit | E4: Checker Code | F4: Total Pcs Checked | G4: Total Defect Pcs | H4: Defect Type | I4: Status | J4: Transferred Back To Unit | K4: Remarks
A5: Auto | B5: Dropdown | C5: Auto | D5: Dropdown | E5: Dropdown | F5: Manual | G5: Manual | H5: Dropdown | I5: Dropdown | J5: Dropdown | K5: Text
J6: if Rejected
A7: 46252 | B7: B9641IS | C7: TR-0751-008 | D7: Unit 1 - Anil Kumar | E7: EMP-004 | F7: 2380 | G7: 120 | H7: Untrimmed Thread | I7: Rejected | J7: Unit 1 - Anil Kumar | K7: Re-trim and resubmit
A8: 46253 | B8: B9641IS | C8: TR-0751-008 | D8: Unit 1 - Anil Kumar | E8: EMP-004 | F8: 2450 | G8: 60 | H8: Handle Out | I8: Approved
A9: 46255 | B9: B9646IS | C9: TR-0751-009 | D9: Unit 2 - Mahipal | E9: EMP-005 | F9: 3320 | G9: 180 | H9: Improper Hem | I9: Rejected | J9: Unit 2 - Mahipal | K9: Hem re-stitch
A10: 46257 | B10: B9646IS | C10: TR-0751-009 | D10: Unit 2 - Mahipal | E10: EMP-005 | F10: 3410 | G10: 90 | H10: Without Label | I10: Approved | K10: Labels attached at finishing
A11: 46258 | B11: B9652IS | C11: TR-0752-101 | D11: Unit 3 - Ramesh | E11: EMP-004 | F11: 1860 | G11: 140 | H11: Without Stitch | I11: Rejected | J11: Unit 3 - Ramesh | K11: Gusset seam open
A12: 46260 | B12: B9658IS | C12: PU-0330-045 | D12: Unit 4 - Suresh | E12: EMP-005 | F12: 4780 | G12: 210 | H12: Stain | I12: Approved | K12: Spot cleaned
A13: 46262 | B13: B9663IS | C13: TB-0910-012 | D13: Unit 1 - Anil Kumar | E13: EMP-004 | F13: 2890 | G13: 105 | H13: Double Stitch | I13: Approved

Sheet Internal Checker Report
A1: Role Acess - QC Dept (Checker) | C1: SEKAWATI IMPEX
C2: Internal Record
A3: Date | B3: Checker Code | C3: Name | D3: Style No | E3: Total Pcs Checked | F3: Total Defect
A4: Auto | B4: Auto | C4: Dropdown | D4: Auto | E4: Manual | F4: Manual
A5: Checker code range: | B5: 1-25
A6: 46252 | B6: EMP-004 | C6: Sunita Devi | D6: TR-0751-008 | E6: 2380 | F6: 120
A7: 46253 | B7: EMP-004 | C7: Sunita Devi | D7: TR-0751-008 | E7: 2450 | F7: 60
A8: 46255 | B8: EMP-005 | C8: Rekha Sharma | D8: TR-0751-009 | E8: 3320 | F8: 180
A9: 46257 | B9: EMP-005 | C9: Rekha Sharma | D9: TR-0751-009 | E9: 3410 | F9: 90
A10: 46258 | B10: EMP-004 | C10: Sunita Devi | D10: TR-0752-101 | E10: 1860 | F10: 140
A11: 46260 | B11: EMP-005 | C11: Rekha Sharma | D11: PU-0330-045 | E11: 4780 | F11: 210
A12: 46262 | B12: EMP-004 | C12: Sunita Devi | D12: TB-0910-012 | E12: 2890 | F12: 105
A15: Note - Defect master attch for selecting style wise defects

Sheet Finished Checker
A1: Role Acess - QC Dept (Checker) | L1: SEKAWATI IMPEX
L2: Daily QC Record (Tailor Size)
A4: Order No | B4: Checker Code | C4: Name | D4: Date | E4: Checked Psc | F4: Untrimmed Thread | G4: Handle out | H4: Handle size | I4: Handle Alter | J4: Without Label | K4: Slanted Lable | L4: Double Lupi | M4: Without Lupi | N4: Wrong side lupi | O4: Weaving defect | P4: Cut/hole | Q4: Improper Hem | R4: Double Stitch | S4: without stich | T4: Torn | U4: Strain | V4: Alter | W4: Total pieces passed | X4: Projected | Y4: Defects %
A5: Dropdown | B5: Auto | C5: Dropdown | D5: Auto | E5: Manual | F5: master of defects (manul entry in int ) | W5: Manual | X5: Auto | Y5: Auto
A6: Dropdown | B6: Dropdown
A7: B9641IS | B7: EMP-004 | C7: Sunita Devi | D7: 46252 | E7: 2380 | F7: 22 | G7: 14 | H7: 8 | I7: 6 | J7: 5 | K7: 4 | L7: 3 | M7: 2 | N7: 3 | O7: 6 | P7: 4 | Q7: 9 | R7: 7 | S7: 5 | T7: 3 | U7: 12 | V7: 7 | W7: =E7-X7 -> 2260 | X7: =SUM(F7:V7) -> 120 | Y7: =IFERROR(X7/E7,0) -> 0.050420168
A8: B9641IS | B8: EMP-004 | C8: Sunita Devi | D8: 46253 | E8: 2450 | F8: 15 | G8: 10 | H8: 6 | I8: 4 | J8: 3 | K8: 3 | L8: 2 | M8: 2 | N8: 1 | O8: 4 | P8: 3 | Q8: 6 | R8: 5 | S8: 3 | T8: 2 | U8: 8 | V8: 5 | W8: =E8-X8 -> 2368 | X8: =SUM(F8:V8) -> 82 | Y8: =IFERROR(X8/E8,0) -> 0.033469388
A9: B9646IS | B9: EMP-005 | C9: Rekha Sharma | D9: 46255 | E9: 3320 | F9: 28 | G9: 18 | H9: 11 | I9: 9 | J9: 7 | K9: 6 | L9: 4 | M9: 3 | N9: 4 | O9: 8 | P9: 6 | Q9: 14 | R9: 10 | S9: 7 | T9: 5 | U9: 16 | V9: 9 | W9: =E9-X9 -> 3155 | X9: =SUM(F9:V9) -> 165 | Y9: =IFERROR(X9/E9,0) -> 0.049698795
A10: B9646IS | B10: EMP-005 | C10: Rekha Sharma | D10: 46257 | E10: 3410 | F10: 19 | G10: 12 | H10: 7 | I10: 5 | J10: 4 | K10: 4 | L10: 3 | M10: 2 | N10: 2 | O10: 5 | P10: 4 | Q10: 8 | R10: 6 | S10: 4 | T10: 3 | U10: 10 | V10: 6 | W10: =E10-X10 -> 3306 | X10: =SUM(F10:V10) -> 104 | Y10: =IFERROR(X10/E10,0) -> 0.030498534
A11: B9652IS | B11: EMP-004 | C11: Sunita Devi | D11: 46258 | E11: 1860 | F11: 24 | G11: 15 | H11: 9 | I11: 7 | J11: 6 | K11: 5 | L11: 3 | M11: 3 | N11: 3 | O11: 7 | P11: 5 | Q11: 11 | R11: 8 | S11: 6 | T11: 4 | U11: 13 | V11: 8 | W11: =E11-X11 -> 1723 | X11: =SUM(F11:V11) -> 137 | Y11: =IFERROR(X11/E11,0) -> 0.073655914
A12: B9658IS | B12: EMP-005 | C12: Rekha Sharma | D12: 46260 | E12: 4780 | F12: 31 | G12: 20 | H12: 13 | I12: 10 | J12: 8 | K12: 7 | L12: 5 | M12: 4 | N12: 5 | O12: 9 | P12: 7 | Q12: 16 | R12: 12 | S12: 8 | T12: 6 | U12: 19 | V12: 11 | W12: =E12-X12 -> 4589 | X12: =SUM(F12:V12) -> 191 | Y12: =IFERROR(X12/E12,0) -> 0.039958159
A13: B9663IS | B13: EMP-004 | C13: Sunita Devi | D13: 46262 | E13: 2890 | F13: 17 | G13: 11 | H13: 7 | I13: 5 | J13: 4 | K13: 3 | L13: 3 | M13: 2 | N13: 2 | O13: 5 | P13: 4 | Q13: 9 | R13: 6 | S13: 4 | T13: 3 | U13: 11 | V13: 6 | W13: =E13-X13 -> 2788 | X13: =SUM(F13:V13) -> 102 | Y13: =IFERROR(X13/E13,0) -> 0.035294118

Sheet External Secondary Checking
A1: Role Acess - QC Dept (External Agency) | D1: SEKAWATI IMPEX
D2: EXTERNAL SECONDARY CHECKING - INSPECTION REPORT
A3: Date | B3: Order No | C3: Style No | D3: Particulars | E3: Critical | F3: Major | G3: Minor | H3: Total | I3: Remark
A4: Auto | B4: Dropdown | C4: Auto | D4: Auto | E4: Manual | F4: Manual | G4: Manual | H4: Formula | I4: Text
A5: 46251 | D5: Master - InspDefect26 | H5: Critical + Major + Minor
A6: 46252 | D6: Stitch skipping | H6: =SUM(E6:G6) -> 0
A7: 46253 | D7: Open stitch | H7: =SUM(E7:G7) -> 0
A8: 46255 | D8: Sewing shifted / Uneven | H8: =SUM(E8:G8) -> 0
A9: 46257 | D9: Sewing shifted / Gathering | H9: =SUM(E9:G9) -> 0
A10: 46258 | D10: Over / Double stitch | H10: =SUM(E10:G10) -> 0
A11: 46260 | D11: Yarn cutting / Uncut thread | H11: =SUM(E11:G11) -> 0
A12: 46262 | D12: Blind-stitch defect / Open seam | H12: =SUM(E12:G12) -> 0
A13: 46252 | D13: Pilling / Fly yarn | H13: =SUM(E13:G13) -> 0
A14: 46253 | D14: Press | G14: 1 | H14: =SUM(E14:G14) -> 1
A15: 46255 | D15: Over / Doubling stitch | H15: =SUM(E15:G15) -> 0
A16: 46257 | D16: Fabric no strength / Fabric fault | H16: =SUM(E16:G16) -> 0
A17: 46252 | D17: Side stitch / Overlock | H17: =SUM(E17:G17) -> 0
A18: 46253 | D18: Colour difference / Shade | H18: =SUM(E18:G18) -> 0
A19: 46255 | D19: Size difference | H19: =SUM(E19:G19) -> 0
A20: 46257 | D20: Breakage / Damage / Eyelet breakage | H20: =SUM(E20:G20) -> 0
A21: 46258 | D21: Needle hole | H21: =SUM(E21:G21) -> 0
A22: 46260 | D22: Thread breakage / Broken stitch | H22: =SUM(E22:G22) -> 0
A23: 46262 | D23: Dirt / Spot | H23: =SUM(E23:G23) -> 0
A24: 46252 | D24: Walking shade / Running shade | H24: =SUM(E24:G24) -> 0
A25: 46253 | D25: Overlock tension | H25: =SUM(E25:G25) -> 0
A26: 46255 | D26: Label mistake | H26: =SUM(E26:G26) -> 0
... A31: 46257 | D31: Fastener opening / Closing defect | H31: =SUM(E31:G31) -> 0
D32: Total | E32: =SUM(E6:E31) -> 0 | F32: =SUM(F6:F31) -> 0 | G32: =SUM(G6:G31) -> 1 | H32: =SUM(H6:H31) -> 1
D33: Total Inspection Qty | E33: 100 | F33: Pcs
D34: Total Critical Problems | E34: =E32 -> 0 | F34: Pcs
D35: Total Major Problems | E35: =F32 -> 0 | F35: Pcs
D36: Total Minor Problems | E36: =G32 -> 1 | F36: Pcs
D37: Total Defect | E37: =H32 -> 1 | F37: Pcs
D38: Total Pass Quantity | E38: =E33-E37 -> 99 | F38: Pcs
D39: Total Defect Ratio | E39: =IF(E33=0,0,E37/E33) -> 0.01

Sheet Alter Report
A1: Role Acess - Stitching Dept (Supervisor) | E1: SEKAWATI IMPEX
C2: Alter Record
A4: Order No | B4: Style No | C4: Time | D4: Output | E4: Pass/ok | F4: Alter piece | G4: Alter% | H4: Remarks
A5: Dropdown | B5: Auto | C5: Auto Capture | D5: Manual | E5: Manual | F5: Manual | G5: Auto | H5: Text
C6: trigger on submit button | E6: count of pieces passed after alteration | F6: Number
A7: B9641IS | B7: TR-0751-008 | C7: 46254 | D7: 110 | E7: 92 | F7: 18 | G7: =IFERROR(F7/D7,0) -> 0.16363636 | H7: Handle re-attach
A8: B9641IS | B8: TR-0751-008 | C8: 46255 | D8: 80 | E8: 68 | F8: 12 | G8: =IFERROR(F8/D8,0) -> 0.15 | H8: Thread trimming
A9: B9646IS | B9: TR-0751-009 | C9: 46257 | D9: 130 | E9: 105 | F9: 25 | G9: =IFERROR(F9/D9,0) -> 0.19230769 | H9: Hem re-stitch
A10: B9646IS | B10: TR-0751-009 | C10: 46259 | D10: 95 | E10: 74 | F10: 21 | G10: =IFERROR(F10/D10,0) -> 0.22105263 | H10: Label position off
A11: B9652IS | B11: TR-0752-101 | C11: 46260 | D11: 110 | E11: 88 | F11: 22 | G11: =IFERROR(F11/D11,0) -> 0.2 | H11: Gusset seam closed
A12: B9658IS | B12: PU-0330-045 | C12: 46262 | D12: 140 | E12: 121 | F12: 19 | G12: =IFERROR(F12/D12,0) -> 0.13571429 | H12: Stain removal
A13: B9663IS | B13: TB-0910-012 | C13: 46264 | D13: 85 | E13: 62 | F13: 23 | G13: =IFERROR(F13/D13,0) -> 0.27058824 | H13: Print misalignment - moved to scrap

Sheet Spot Rectification-Scrap
A1: Role Acess - QC / Packing Dept | C1: SEKAWATI IMPEX
C2: Spot Rectification & Scrap / Online Sale
A4: Date | B4: Order No | C4: Style No | D4: Qty Received for Rectification | E4: Sold Online-Domestic Qty | F4: Scrap Qty | G4: Scrap % of Consignment | H4: Authorised By | I4: Remarks
A5: Auto | B5: Dropdown | C5: Auto | D5: Manual | E5: Manual | F5: Manual | G5: Formula | H5: Dropdown | I5: Text
G6: Scrap Qty / Order Qty from the Order sheet (2-3% norm)
A7: 46255 | B7: B9641IS | C7: TR-0751-008 | D7: 90 | E7: 40 | F7: 32 | G7: =IFERROR(F7/INDEX(Order!$H$7:$H$500,MATCH(B7,Order!$A$7:$A$500,0)),0) -> 0.0064 | H7: Dinesh Sir | I7: 18 reissued to stitching
A8: 46256 | B8: B9641IS | C8: TR-0751-008 | D8: 70 | E8: 35 | F8: 24 | G8: =IFERROR(F8/INDEX(Order!$H$7:$H$500,MATCH(B8,Order!$A$7:$A$500,0)),0) -> 0.0048 | H8: Dinesh Sir
A9: 46258 | B9: B9646IS | C9: TR-0751-009 | D9: 140 | E9: 60 | F9: 55 | G9: =IFERROR(F9/INDEX(Order!$H$7:$H$500,MATCH(B9,Order!$A$7:$A$500,0)),0) -> 0.0078571429 | H9: Dinesh Sir | I9: 25 reissued
A10: 46260 | B10: B9646IS | C10: TR-0751-009 | D10: 95 | E10: 45 | F10: 34 | G10: =IFERROR(F10/INDEX(Order!$H$7:$H$500,MATCH(B10,Order!$A$7:$A$500,0)),0) -> 0.0048571429 | H10: Dinesh Sir
A11: 46261 | B11: B9652IS | C11: TR-0752-101 | D11: 110 | E11: 48 | F11: 42 | G11: =IFERROR(F11/INDEX(Order!$H$7:$H$500,MATCH(B11,Order!$A$7:$A$500,0)),0) -> 0.0105 | H11: Dinesh Sir | I11: Gusset defects
A12: 46263 | B12: B9658IS | C12: PU-0330-045 | D12: 160 | E12: 72 | F12: 60 | G12: =IFERROR(F12/INDEX(Order!$H$7:$H$500,MATCH(B12,Order!$A$7:$A$500,0)),0) -> 0.006 | H12: Dinesh Sir | I12: 28 reissued
A13: 46265 | B13: B9663IS | C13: TB-0910-012 | D13: 85 | E13: 36 | F13: 31 | G13: =IFERROR(F13/INDEX(Order!$H$7:$H$500,MATCH(B13,Order!$A$7:$A$500,0)),0) -> 0.0051666667 | H13: Dinesh Sir | I13: Print defects - scrap

Sheet Rejected
A1: Role Acess - QC Dept (Checker) | C1: SEKAWATI IMPEX
C2: Rejected Record Format
A4: Date | B4: Order No | C4: Style No | D4: Order Qty | E4: Cutting Qty | F4: Packed Qty | G4: Rejected Qty | H4: Check By | I4: Reason of Defects | J4: Remarks
A5: Auto | B5: Dropdown | C5: Manual | D5: Auto | E5: Manual | F5: Manual | G5: Formula | H5: Dropdown | I5: Dropdown | J5: Text
D6: From Order | E6: From Cutting Issue | F6: Master | G6: Cutting Qty - Packed Qty | H6: Master - Employee | I6: Master - RejectReason
B7: B9641IS | C7: TR-0751-008 | D7: 5000 | E7: 4900 | F7: 4780 | G7: =IF(E7=0,0,E7-F7) -> 120 | H7: Sunita Devi | I7: Stitching | J7: Handle stitching out of line
B8: B9646IS | C8: TR-0751-009 | D8: 7000 | E8: 6800 | F8: 6620 | G8: =IF(E8=0,0,E8-F8) -> 180 | H8: Rekha Sharma | I8: Fabric | J8: Weaving fault in body panel
B9: B9652IS | C9: TR-0752-101 | D9: 4000 | E9: 1800 | F9: 1660 | G9: =IF(E9=0,0,E9-F9) -> 140 | H9: Sunita Devi | I9: Dye | J9: Shade variation after dyeing
B10: B9658IS | C10: PU-0330-045 | D10: 10000 | E10: 4600 | F10: 4480 | G10: =IF(E10=0,0,E10-F10) -> 120 | H10: Rekha Sharma | I10: Hard Stain | J10: Oil stain near base
B11: B9663IS | C11: TB-0910-012 | D11: 6000 | E11: 2800 | F11: 2720 | G11: =IF(E11=0,0,E11-F11) -> 80 | H11: Sunita Devi | I11: Handle Out | J11: Handle placement off
